Workbook

Sheet Raw Data
A1: LA ROCHE-POSAY — Sales Forecasting Raw Dataset | Oct 1 – Dec 25, 2021
A2: Date | B2: Day# | C2: Day Name | D2: Holiday? | E2: Weekend? | F2: Newsletter? | G2: Sales (units)
A3: 44470 | B3: 6 | C3: Saturday | D3: 0 | E3: 0 | F3: 0 | G3: 2042
A4: 44471 | B4: 7 | C4: Sunday | D4: 0 | E4: 1 | F4: 0 | G4: 4152
A5: 44472 | B5: 1 | C5: Monday | D5: 0 | E5: 1 | F5: 0 | G5: 4289
A6: 44473 | B6: 2 | C6: Tuesday | D6: 0 | E6: 0 | F6: 0 | G6: 2454
A7: 44474 | B7: 3 | C7: Wednesday | D7: 0 | E7: 0 | F7: 0 | G7: 2544
A8: 44475 | B8: 4 | C8: Thursday | D8: 0 | E8: 0 | F8: 0 | G8: 2686
A9: 44476 | B9: 5 | C9: Friday | D9: 0 | E9: 0 | F9: 0 | G9: 2792
A10: 44477 | B10: 6 | C10: Saturday | D10: 0 | E10: 0 | F10: 0 | G10: 2246
A11: 44478 | B11: 7 | C11: Sunday | D11: 0 | E11: 1 | F11: 0 | G11: 4078
A12: 44479 | B12: 1 | C12: Monday | D12: 0 | E12: 1 | F12: 0 | G12: 3949
A13: 44480 | B13: 2 | C13: Tuesday | D13: 0 | E13: 0 | F13: 0 | G13: 2687
A14: 44481 | B14: 3 | C14: Wednesday | D14: 0 | E14: 0 | F14: 0 | G14: 2737
... A76: 44543 | B76: 2 | C76: Tuesday | D76: 0 | E76: 0 | F76: 0 | G76: 2394
A77: 44544 | B77: 3 | C77: Wednesday | D77: 0 | E77: 0 | F77: 0 | G77: —
A78: 44545 | B78: 4 | C78: Thursday | D78: 0 | E78: 0 | F78: 0 | G78: —
A79: 44546 | B79: 5 | C79: Friday | D79: 0 | E79: 0 | F79: 0 | G79: —
A80: 44547 | B80: 6 | C80: Saturday | D80: 0 | E80: 0 | F80: 0 | G80: —
A81: 44548 | B81: 7 | C81: Sunday | D81: 1 | E81: 1 | F81: 0 | G81: —
A82: 44549 | B82: 1 | C82: Monday | D82: 1 | E82: 1 | F82: 0 | G82: —
A83: 44550 | B83: 2 | C83: Tuesday | D83: 1 | E83: 0 | F83: 0 | G83: —
A84: 44551 | B84: 3 | C84: Wednesday | D84: 1 | E84: 0 | F84: 1 | G84: —
A85: 44552 | B85: 4 | C85: Thursday | D85: 1 | E85: 0 | F85: 0 | G85: —
A86: 44553 | B86: 5 | C86: Friday | D86: 1 | E86: 0 | F86: 0 | G86: —
A87: 44554 | B87: 6 | C87: Saturday | D87: 1 | E87: 0 | F87: 0 | G87: —
A88: 44555 | B88: 7 | C88: Sunday | D88: 1 | E88: 1 | F88: 0 | G88: —

Sheet Model 1 - Global Average
A1: MODEL 1 — Global Average Forecast
A2: Method: Use the simple arithmetic mean of ALL learning data sales as the forecast for every single day. This is the baseline benchmark — the simplest possible model.
A3: Global Average (β) | B3: =AVERAGE('Raw Data'!G3:G61) -> 2950.9831 | C3: ← AVERAGE of all 59 learning observations (Oct 1 – Nov 28)
A4: Date | B4: Day# | C4: Day Name | D4: Holiday? | E4: Weekend? | F4: Newsletter? | G4: Real Sales | H4: Forecast (=$B$3) | I4: Difference | J4: Abs Error Rate
A5: LEARNING DATA (59 observations) Oct 1 – Nov 28, 2021 | Model trained on this data
A6: ='Raw Data'!A4 -> 44471 | B6: ='Raw Data'!B4 -> 7 | C6: ='Raw Data'!C4 -> Sunday | D6: ='Raw Data'!D4 -> 0 | E6: ='Raw Data'!E4 -> 1 | F6: ='Raw Data'!F4 -> 0 | G6: ='Raw Data'!G3 -> 2042 | H6: =$B$3 -> 2950.9831 | I6: =G6-H6 -> -908.98305 | J6: =ABS((G6-H6)/G6) -> 0.44514351
A7: ='Raw Data'!A5 -> 44472 | B7: ='Raw Data'!B5 -> 1 | C7: ='Raw Data'!C5 -> Monday | D7: ='Raw Data'!D5 -> 0 | E7: ='Raw Data'!E5 -> 1 | F7: ='Raw Data'!F5 -> 0 | G7: ='Raw Data'!G5 -> 4289 | H7: =$B$3 -> 2950.9831 | I7: =G7-H7 -> 1338.0169 | J7: =ABS((G7-H7)/G7) -> 0.31196478
A8: ='Raw Data'!A6 -> 44473 | B8: ='Raw Data'!B6 -> 2 | C8: ='Raw Data'!C6 -> Tuesday | D8: ='Raw Data'!D6 -> 0 | E8: ='Raw Data'!E6 -> 0 | F8: ='Raw Data'!F6 -> 0 | G8: ='Raw Data'!G6 -> 2454 | H8: =$B$3 -> 2950.9831 | I8: =G8-H8 -> -496.98305 | J8: =ABS((G8-H8)/G8) -> 0.20251958
A9: ='Raw Data'!A7 -> 44474 | B9: ='Raw Data'!B7 -> 3 | C9: ='Raw Data'!C7 -> Wednesday | D9: ='Raw Data'!D7 -> 0 | E9: ='Raw Data'!E7 -> 0 | F9: ='Raw Data'!F7 -> 0 | G9: ='Raw Data'!G7 -> 2544 | H9: =$B$3 -> 2950.9831 | I9: =G9-H9 -> -406.98305 | J9: =ABS((G9-H9)/G9) -> 0.15997761
A10: ='Raw Data'!A8 -> 44475 | B10: ='Raw Data'!B8 -> 4 | C10: ='Raw Data'!C8 -> Thursday | D10: ='Raw Data'!D8 -> 0 | E10: ='Raw Data'!E8 -> 0 | F10: ='Raw Data'!F8 -> 0 | G10: ='Raw Data'!G8 -> 2686 | H10: =$B$3 -> 2950.9831 | I10: =G10-H10 -> -264.98305 | J10: =ABS((G10-H10)/G10) -> 0.098653407
A11: ='Raw Data'!A9 -> 44476 | B11: ='Raw Data'!B9 -> 5 | C11: ='Raw Data'!C9 -> Friday | D11: ='Raw Data'!D9 -> 0 | E11: ='Raw Data'!E9 -> 0 | F11: ='Raw Data'!F9 -> 0 | G11: ='Raw Data'!G9 -> 2792 | H11: =$B$3 -> 2950.9831 | I11: =G11-H11 -> -158.98305 | J11: =ABS((G11-H11)/G11) -> 0.056942353
A12: ='Raw Data'!A10 -> 44477 | B12: ='Raw Data'!B10 -> 6 | C12: ='Raw Data'!C10 -> Saturday | D12: ='Raw Data'!D10 -> 0 | E12: ='Raw Data'!E10 -> 0 | F12: ='Raw Data'!F10 -> 0 | G12: ='Raw Data'!G10 -> 2246 | H12: =$B$3 -> 2950.9831 | I12: =G12-H12 -> -704.98305 | J12: =ABS((G12-H12)/G12) -> 0.31388382
A13: ='Raw Data'!A11 -> 44478 | B13: ='Raw Data'!B11 -> 7 | C13: ='Raw Data'!C11 -> Sunday | D13: ='Raw Data'!D11 -> 0 | E13: ='Raw Data'!E11 -> 1 | F13: ='Raw Data'!F11 -> 0 | G13: ='Raw Data'!G11 -> 4078 | H13: =$B$3 -> 2950.9831 | I13: =G13-H13 -> 1127.0169 | J13: =ABS((G13-H13)/G13) -> 0.27636512
A14: ='Raw Data'!A12 -> 44479 | B14: ='Raw Data'!B12 -> 1 | C14: ='Raw Data'!C12 -> Monday | D14: ='Raw Data'!D12 -> 0 | E14: ='Raw Data'!E12 -> 1 | F14: ='Raw Data'!F12 -> 0 | G14: ='Raw Data'!G12 -> 3949 | H14: =$B$3 -> 2950.9831 | I14: =G14-H14 -> 998.01695 | J14: =ABS((G14-H14)/G14) -> 0.2527265
A15: ='Raw Data'!A13 -> 44480 | B15: ='Raw Data'!B13 -> 2 | C15: ='Raw Data'!C13 -> Tuesday | D15: ='Raw Data'!D13 -> 0 | E15: ='Raw Data'!E13 -> 0 | F15: ='Raw Data'!F13 -> 0 | G15: ='Raw Data'!G13 -> 2687 | H15: =$B$3 -> 2950.9831 | I15: =G15-H15 -> -263.98305 | J15: =ABS((G15-H15)/G15) -> 0.09824453
A16: ='Raw Data'!A14 -> 44481 | B16: ='Raw Data'!B14 -> 3 | C16: ='Raw Data'!C14 -> Wednesday | D16: ='Raw Data'!D14 -> 0 | E16: ='Raw Data'!E14 -> 0 | F16: ='Raw Data'!F14 -> 0 | G16: ='Raw Data'!G14 -> 2737 | H16: =$B$3 -> 2950.9831 | I16: =G16-H16 -> -213.98305 | J16: =ABS((G16-H16)/G16) -> 0.078181604
A17: ='Raw Data'!A15 -> 44482 | B17: ='Raw Data'!B15 -> 4 | C17: ='Raw Data'!C15 -> Thursday | D17: ='Raw Data'!D15 -> 0 | E17: ='Raw Data'!E15 -> 0 | F17: ='Raw Data'!F15 -> 1 | G17: ='Raw Data'!G15 -> 5817 | H17: =$B$3 -> 2950.9831 | I17: =G17-H17 -> 2866.0169 | J17: =ABS((G17-H17)/G17) -> 0.49269674
A18: ='Raw Data'!A16 -> 44483 | B18: ='Raw Data'!B16 -> 5 | C18: ='Raw Data'!C16 -> Friday | D18: ='Raw Data'!D16 -> 0 | E18: ='Raw Data'!E16 -> 0 | F18: ='Raw Data'!F16 -> 0 | G18: ='Raw Data'!G16 -> 2855 | H18: =$B$3 -> 2950.9831 | I18: =G18-H18 -> -95.983051 | J18: =ABS((G18-H18)/G18) -> 0.033619282
... A39: ='Raw Data'!A37 -> 44504 | B39: ='Raw Data'!B37 -> 5 | C39: ='Raw Data'!C37 -> Friday | D39: ='Raw Data'!D37 -> 1 | E39: ='Raw Data'!E37 -> 0 | F39: ='Raw Data'!F37 -> 0 | G39: ='Raw Data'!G37 -> 1983 | H39: =$B$3 -> 2950.9831 | I39: =G39-H39 -> -967.98305 | J39: =ABS((G39-H39)/G39) -> 0.48814072
A40: ='Raw Data'!A38 -> 44505 | B40: ='Raw Data'!B38 -> 6 | C40: ='Raw Data'!C38 -> Saturday | D40: ='Raw Data'!D38 -> 1 | E40: ='Raw Data'!E38 -> 0 | F40: ='Raw Data'!F38 -> 0 | G40: ='Raw Data'!G38 -> 2214 | H40: =$B$3 -> 2950.9831 | I40: =G30-H40 -> -1006.9831 | J40: =ABS((G30-H40)/G30) -> 0.5179954
A41: ='Raw Data'!A39 -> 44506 | B41: ='Raw Data'!B39 -> 7 | C41: ='Raw Data'!C39 -> Sunday | D41: ='Raw Data'!D39 -> 1 | E41: ='Raw Data'!E39 -> 1 | F41: ='Raw Data'!F39 -> 0 | G41: ='Raw Data'!G39 -> 4930 | H41: =$B$3 -> 2950.9831 | I41: =G31-H41 -> 4.0169492 | J41: =ABS((G31-H41)/G31) -> 0.0013593737
A42: ='Raw Data'!A40 -> 44507 | B42: ='Raw Data'!B40 -> 1 | C42: ='Raw Data'!C40 -> Monday | D42: ='Raw Data'!D40 -> 1 | E42: ='Raw Data'!E40 -> 1 | F42: ='Raw Data'!F40 -> 0 | G42: ='Raw Data'!G30 -> 4089 | H42: =$B$3 -> 2950.9831 | I42: =G32-H42 -> 1138.0169 | J42: =ABS((G32-H42)/G32) -> 0.2783118
A43: ='Raw Data'!A41 -> 44508 | B43: ='Raw Data'!B41 -> 2 | C43: ='Raw Data'!C41 -> Tuesday | D43: ='Raw Data'!D41 -> 0 | E43: ='Raw Data'!E41 -> 0 | F43: ='Raw Data'!F41 -> 0 | G43: ='Raw Data'!G31 -> 2104 | H43: =$B$3 -> 2950.9831 | I43: =G33-H43 -> -846.98305 | J43: =ABS((G33-H43)/G33) -> 0.40255848
A44: ='Raw Data'!A42 -> 44509 | B44: ='Raw Data'!B42 -> 3 | C44: ='Raw Data'!C42 -> Wednesday | D44: ='Raw Data'!D42 -> 0 | E44: ='Raw Data'!E42 -> 0 | F44: ='Raw Data'!F42 -> 1 | G44: ='Raw Data'!G32 -> 4240 | H44: =$B$3 -> 2950.9831 | I44: =G34-H44 -> 1289.0169 | J44: =ABS((G34-H44)/G34) -> 0.30401343
A45: ='Raw Data'!A43 -> 44510 | B45: ='Raw Data'!B43 -> 4 | C45: ='Raw Data'!C43 -> Thursday | D45: ='Raw Data'!D43 -> 0 | E45: ='Raw Data'!E43 -> 0 | F45: ='Raw Data'!F43 -> 0 | G45: ='Raw Data'!G33 -> 2190 | H45: =$B$3 -> 2950.9831 | I45: =G35-H45 -> -760.98305 | J45: =ABS((G35-H45)/G35) -> 0.34748085
A46: ='Raw Data'!A44 -> 44511 | B46: ='Raw Data'!B44 -> 5 | C46: ='Raw Data'!C44 -> Friday | D46: ='Raw Data'!D44 -> 0 | E46: ='Raw Data'!E44 -> 0 | F46: ='Raw Data'!F44 -> 0 | G46: ='Raw Data'!G34 -> 1950 | H46: =$B$3 -> 2950.9831 | I46: =G36-H46 -> -1000.9831 | J46: =ABS((G36-H46)/G36) -> 0.51332464
A47: ='Raw Data'!A45 -> 44512 | B47: ='Raw Data'!B45 -> 6 | C47: ='Raw Data'!C45 -> Saturday | D47: ='Raw Data'!D45 -> 0 | E47: ='Raw Data'!E45 -> 0 | F47: ='Raw Data'!F45 -> 0 | G47: ='Raw Data'!G35 -> 1748 | H47: =$B$3 -> 2950.9831 | I47: =G37-H47 -> -1202.9831 | J47: =ABS((G37-H47)/G37) -> 0.68820541
A48: ='Raw Data'!A46 -> 44513 | B48: ='Raw Data'!B46 -> 7 | C48: ='Raw Data'!C46 -> Sunday | D48: ='Raw Data'!D46 -> 0 | E48: ='Raw Data'!E46 -> 1 | F48: ='Raw Data'!F46 -> 0 | G48: ='Raw Data'!G36 -> 2186 | H48: =$B$3 -> 2950.9831 | I48: =G38-H48 -> -764.98305 | J48: =ABS((G38-H48)/G38) -> 0.3499465
A49: ='Raw Data'!A47 -> 44514 | B49: ='Raw Data'!B47 -> 1 | C49: ='Raw Data'!C47 -> Monday | D49: ='Raw Data'!D47 -> 0 | E49: ='Raw Data'!E47 -> 1 | F49: ='Raw Data'!F47 -> 0 | G49: ='Raw Data'!G37 -> 1983 | H49: =$B$3 -> 2950.9831 | I49: =G39-H49 -> -967.98305 | J49: =ABS((G39-H49)/G39) -> 0.48814072
A50: ='Raw Data'!A48 -> 44515 | B50: ='Raw Data'!B48 -> 2 | C50: ='Raw Data'!C48 -> Tuesday | D50: ='Raw Data'!D48 -> 0 | E50: ='Raw Data'!E48 -> 0 | F50: ='Raw Data'!F48 -> 0 | G50: ='Raw Data'!G38 -> 2214 | H50: =$B$3 -> 2950.9831 | I50: =G50-H50 -> -736.98305 | J50: =ABS((G50-H50)/G50) -> 0.33287401
A51: ='Raw Data'!A49 -> 44516 | B51: ='Raw Data'!B49 -> 3 | C51: ='Raw Data'!C49 -> Wednesday | D51: ='Raw Data'!D49 -> 0 | E51: ='Raw Data'!E49 -> 0 | F51: ='Raw Data'!F49 -> 0 | G51: ='Raw Data'!G39 -> 4930 | H51: =$B$3 -> 2950.9831 | I51: =G51-H51 -> 1979.0169 | J51: =ABS((G51-H51)/G51) -> 0.40142332
A52: ='Raw Data'!A50 -> 44517 | B52: ='Raw Data'!B50 -> 4 | C52: ='Raw Data'!C50 -> Thursday | D52: ='Raw Data'!D50 -> 0 | E52: ='Raw Data'!E50 -> 0 | F52: ='Raw Data'!F50 -> 0 | G52: ='Raw Data'!G50 -> 2159 | H52: =$B$3 -> 2950.9831 | I52: =G52-H52 -> -791.98305 | J52: =ABS((G52-H52)/G52) -> 0.36682865
A53: ='Raw Data'!A51 -> 44518 | B53: ='Raw Data'!B51 -> 5 | C53: ='Raw Data'!C51 -> Friday | D53: ='Raw Data'!D51 -> 0 | E53: ='Raw Data'!E51 -> 0 | F53: ='Raw Data'!F51 -> 0 | G53: ='Raw Data'!G51 -> 2747 | H53: =$B$3 -> 2950.9831 | I53: =G53-H53 -> -203.98305 | J53: =ABS((G53-H53)/G53) -> 0.074256662
A54: ='Raw Data'!A52 -> 44519 | B54: ='Raw Data'!B52 -> 6 | C54: ='Raw Data'!C52 -> Saturday | D54: ='Raw Data'!D52 -> 0 | E54: ='Raw Data'!E52 -> 0 | F54: ='Raw Data'!F52 -> 0 | G54: ='Raw Data'!G52 -> 2382 | H54: =$B$3 -> 2950.9831 | I54: =G54-H54 -> -568.98305 | J54: =ABS((G54-H54)/G54) -> 0.23886778
A55: ='Raw Data'!A53 -> 44520 | B55: ='Raw Data'!B53 -> 7 | C55: ='Raw Data'!C53 -> Sunday | D55: ='Raw Data'!D53 -> 0 | E55: ='Raw Data'!E53 -> 1 | F55: ='Raw Data'!F53 -> 0 | G55: ='Raw Data'!G53 -> 2551 | H55: =$B$3 -> 2950.9831 | I55: =G55-H55 -> -399.98305 | J55: =ABS((G55-H55)/G55) -> 0.15679461
A56: ='Raw Data'!A54 -> 44521 | B56: ='Raw Data'!B54 -> 1 | C56: ='Raw Data'!C54 -> Monday | D56: ='Raw Data'!D54 -> 0 | E56: ='Raw Data'!E54 -> 1 | F56: ='Raw Data'!F54 -> 0 | G56: ='Raw Data'!G54 -> 3653 | H56: =$B$3 -> 2950.9831 | I56: =G56-H56 -> 702.01695 | J56: =ABS((G56-H56)/G56) -> 0.19217546
A57: ='Raw Data'!A55 -> 44522 | B57: ='Raw Data'!B55 -> 2 | C57: ='Raw Data'!C55 -> Tuesday | D57: ='Raw Data'!D55 -> 0 | E57: ='Raw Data'!E55 -> 0 | F57: ='Raw Data'!F55 -> 0 | G57: ='Raw Data'!G55 -> 2375 | H57: =$B$3 -> 2950.9831 | I57: =G57-H57 -> -575.98305 | J57: =ABS((G57-H57)/G57) -> 0.24251918
A58: ='Raw Data'!A56 -> 44523 | B58: ='Raw Data'!B56 -> 3 | C58: ='Raw Data'!C56 -> Wednesday | D58: ='Raw Data'!D56 -> 0 | E58: ='Raw Data'!E56 -> 0 | F58: ='Raw Data'!F56 -> 0 | G58: ='Raw Data'!G56 -> 2545 | H58: =$B$3 -> 2950.9831 | I58: =G58-H58 -> -405.98305 | J58: =ABS((G58-H58)/G58) -> 0.15952183
A59: ='Raw Data'!A57 -> 44524 | B59: ='Raw Data'!B57 -> 4 | C59: ='Raw Data'!C57 -> Thursday | D59: ='Raw Data'!D57 -> 0 | E59: ='Raw Data'!E57 -> 0 | F59: ='Raw Data'!F57 -> 0 | G59: ='Raw Data'!G57 -> 2820 | H59: =$B$3 -> 2950.9831 | I59: =G59-H59 -> -130.98305 | J59: =ABS((G59-H59)/G59) -> 0.04644789
A60: ='Raw Data'!A58 -> 44525 | B60: ='Raw Data'!B58 -> 5 | C60: ='Raw Data'!C58 -> Friday | D60: ='Raw Data'!D58 -> 0 | E60: ='Raw Data'!E58 -> 0 | F60: ='Raw Data'!F58 -> 0 | G60: ='Raw Data'!G58 -> 2149 | H60: =$B$3 -> 2950.9831 | I60: =G60-H60 -> -801.98305 | J60: =ABS((G60-H60)/G60) -> 0.37318895
...

Sheet Model 2 - Day of Week Avg
A1: MODEL 2 — Day-of-Week Average Forecast
A2: Method: Compute a separate average for each day of the week (Mon–Sun) from Learning Data. Forecast = average sales on that same weekday. Better than global avg — captures weekly seasonality.
I3: Day-of-Week Lookup Table (used by VLOOKUP in col H)
I4: Day # | J4: Day Name | K4: Avg Sales Formula | N4: Day# | O4: Day Name | P4: Avg Sales
I5: 1 | J5: Monday | K5: =AVERAGEIF('Raw Data'!B3:B61,1,'Raw Data'!G3:G61) -> 3684.1111 | N5: 1 | O5: Monday | P5: =AVERAGEIF('Raw Data'!B3:B61,1,'Raw Data'!G3:G61) -> 3684.1111
A6: Date | B6: Day# | C6: Day Name | D6: Holiday? | E6: Weekend? | F6: Newsletter? | G6: Real Sales | H6: Day-Avg Forecast | I6: 2 | J6: Tuesday | K6: =AVERAGEIF('Raw Data'!B3:B61,2,'Raw Data'!G3:G61) -> 2327.75 | L6: Difference | M6: Abs Error Rate | N6: 2 | O6: Tuesday | P6: =AVERAGEIF('Raw Data'!B3:B61,2,'Raw Data'!G3:G61) -> 2327.75
A7: LEARNING DATA (59 obs) Oct 1 – Nov 28, 2021 | N7: 3 | O7: Wednesday | P7: =AVERAGEIF('Raw Data'!B3:B61,3,'Raw Data'!G3:G61) -> 2795.5
A8: ='Raw Data'!A4 -> 44471 | B8: ='Raw Data'!B4 -> 7 | C8: ='Raw Data'!C4 -> Sunday | D8: ='Raw Data'!D4 -> 0 | E8: ='Raw Data'!E4 -> 1 | F8: ='Raw Data'!F4 -> 0 | G8: ='Raw Data'!G3 -> 2042 | H8: =VLOOKUP(B8,$N$5:$P$11,3,FALSE()) -> 3670 | I8: 4 | J8: Thursday | K8: =AVERAGEIF('Raw Data'!B3:B61,4,'Raw Data'!G3:G61) -> 2911.375 | L8: =G8-H8 -> -1628 | M8: =ABS((G8-H8)/G8) -> 0.79725759 | N8: 4 | O8: Thursday | P8: =AVERAGEIF('Raw Data'!B3:B61,4,'Raw Data'!G3:G61) -> 2911.375
A9: ='Raw Data'!A5 -> 44472 | B9: ='Raw Data'!B5 -> 1 | C9: ='Raw Data'!C5 -> Monday | D9: ='Raw Data'!D5 -> 0 | E9: ='Raw Data'!E5 -> 1 | F9: ='Raw Data'!F5 -> 0 | G9: ='Raw Data'!G5 -> 4289 | H9: =VLOOKUP(B9,$N$5:$P$11,3,FALSE()) -> 3684.1111 | I9: 5 | J9: Friday | K9: =AVERAGEIF('Raw Data'!B3:B61,5,'Raw Data'!G3:G61) -> 2723.75 | L9: =G9-H9 -> 604.88889 | M9: =ABS((G9-H9)/G9) -> 0.14103262 | N9: 5 | O9: Friday | P9: =AVERAGEIF('Raw Data'!B3:B61,5,'Raw Data'!G3:G61) -> 2723.75
A10: ='Raw Data'!A6 -> 44473 | B10: ='Raw Data'!B6 -> 2 | C10: ='Raw Data'!C6 -> Tuesday | D10: ='Raw Data'!D6 -> 0 | E10: ='Raw Data'!E6 -> 0 | F10: ='Raw Data'!F6 -> 0 | G10: ='Raw Data'!G6 -> 2454 | H10: =VLOOKUP(B10,$N$5:$P$11,3,FALSE()) -> 2327.75 | I10: 6 | J10: Saturday | K10: =AVERAGEIF('Raw Data'!B3:B61,6,'Raw Data'!G3:G61) -> 2428.2222 | L10: =G10-H10 -> 126.25 | M10: =ABS((G10-H10)/G10) -> 0.051446618 | N10: 6 | O10: Saturday | P10: =AVERAGEIF('Raw Data'!B3:B61,6,'Raw Data'!G3:G61) -> 2428.2222
A11: ='Raw Data'!A7 -> 44474 | B11: ='Raw Data'!B7 -> 3 | C11: ='Raw Data'!C7 -> Wednesday | D11: ='Raw Data'!D7 -> 0 | E11: ='Raw Data'!E7 -> 0 | F11: ='Raw Data'!F7 -> 0 | G11: ='Raw Data'!G7 -> 2544 | H11: =VLOOKUP(B11,$N$5:$P$11,3,FALSE()) -> 2795.5 | I11: 7 | J11: Sunday | K11: =AVERAGEIF('Raw Data'!B3:B61,7,'Raw Data'!G3:G61) -> 3670 | L11: =G11-H11 -> -251.5 | M11: =ABS((G11-H11)/G11) -> 0.098860063 | N11: 7 | O11: Sunday | P11: =AVERAGEIF('Raw Data'!B3:B61,7,'Raw Data'!G3:G61) -> 3670
A12: ='Raw Data'!A8 -> 44475 | B12: ='Raw Data'!B8 -> 4 | C12: ='Raw Data'!C8 -> Thursday | D12: ='Raw Data'!D8 -> 0 | E12: ='Raw Data'!E8 -> 0 | F12: ='Raw Data'!F8 -> 0 | G12: ='Raw Data'!G8 -> 2686 | H12: =VLOOKUP(B12,$N$5:$P$11,3,FALSE()) -> 2911.375 | L12: =G12-H12 -> -225.375 | M12: =ABS((G12-H12)/G12) -> 0.083907297
A13: ='Raw Data'!A9 -> 44476 | B13: ='Raw Data'!B9 -> 5 | C13: ='Raw Data'!C9 -> Friday | D13: ='Raw Data'!D9 -> 0 | E13: ='Raw Data'!E9 -> 0 | F13: ='Raw Data'!F9 -> 0 | G13: ='Raw Data'!G9 -> 2792 | H13: =VLOOKUP(B13,$N$5:$P$11,3,FALSE()) -> 2723.75 | L13: =G13-H13 -> 68.25 | M13: =ABS((G13-H13)/G13) -> 0.024444842
A14: ='Raw Data'!A10 -> 44477 | B14: ='Raw Data'!B10 -> 6 | C14: ='Raw Data'!C10 -> Saturday | D14: ='Raw Data'!D10 -> 0 | E14: ='Raw Data'!E10 -> 0 | F14: ='Raw Data'!F10 -> 0 | G14: ='Raw Data'!G10 -> 2246 | H14: =VLOOKUP(B14,$N$5:$P$11,3,FALSE()) -> 2428.2222 | L14: =G14-H14 -> -182.22222 | M14: =ABS((G14-H14)/G14) -> 0.081131889
A15: ='Raw Data'!A11 -> 44478 | B15: ='Raw Data'!B11 -> 7 | C15: ='Raw Data'!C11 -> Sunday | D15: ='Raw Data'!D11 -> 0 | E15: ='Raw Data'!E11 -> 1 | F15: ='Raw Data'!F11 -> 0 | G15: ='Raw Data'!G11 -> 4078 | H15: =VLOOKUP(B15,$N$5:$P$11,3,FALSE()) -> 3670 | L15: =G15-H15 -> 408 | M15: =ABS((G15-H15)/G15) -> 0.10004904
A16: ='Raw Data'!A12 -> 44479 | B16: ='Raw Data'!B12 -> 1 | C16: ='Raw Data'!C12 -> Monday | D16: ='Raw Data'!D12 -> 0 | E16: ='Raw Data'!E12 -> 1 | F16: ='Raw Data'!F12 -> 0 | G16: ='Raw Data'!G12 -> 3949 | H16: =VLOOKUP(B16,$N$5:$P$11,3,FALSE()) -> 3684.1111 | L16: =G16-H16 -> 264.88889 | M16: =ABS((G16-H16)/G16) -> 0.06707746
A17: ='Raw Data'!A13 -> 44480 | B17: ='Raw Data'!B13 -> 2 | C17: ='Raw Data'!C13 -> Tuesday | D17: ='Raw Data'!D13 -> 0 | E17: ='Raw Data'!E13 -> 0 | F17: ='Raw Data'!F13 -> 0 | G17: ='Raw Data'!G13 -> 2687 | H17: =VLOOKUP(B17,$N$5:$P$11,3,FALSE()) -> 2327.75 | L17: =G17-H17 -> 359.25 | M17: =ABS((G17-H17)/G17) -> 0.13369929
A18: ='Raw Data'!A14 -> 44481 | B18: ='Raw Data'!B14 -> 3 | C18: ='Raw Data'!C14 -> Wednesday | D18: ='Raw Data'!D14 -> 0 | E18: ='Raw Data'!E14 -> 0 | F18: ='Raw Data'!F14 -> 0 | G18: ='Raw Data'!G14 -> 2737 | H18: =VLOOKUP(B18,$N$5:$P$11,3,FALSE()) -> 2795.5 | L18: =G18-H18 -> -58.5 | M18: =ABS((G18-H18)/G18) -> 0.021373767
A19: ='Raw Data'!A15 -> 44482 | B19: ='Raw Data'!B15 -> 4 | C19: ='Raw Data'!C15 -> Thursday | D19: ='Raw Data'!D15 -> 0 | E19: ='Raw Data'!E15 -> 0 | F19: ='Raw Data'!F15 -> 1 | G19: ='Raw Data'!G15 -> 5817 | H19: =VLOOKUP(B19,$N$5:$P$11,3,FALSE()) -> 2911.375 | L19: =G19-H19 -> 2905.625 | M19: =ABS((G19-H19)/G19) -> 0.49950576
A20: ='Raw Data'!A16 -> 44483 | B20: ='Raw Data'!B16 -> 5 | C20: ='Raw Data'!C16 -> Friday | D20: ='Raw Data'!D16 -> 0 | E20: ='Raw Data'!E16 -> 0 | F20: ='Raw Data'!F16 -> 0 | G20: ='Raw Data'!G16 -> 2855 | H20: =VLOOKUP(B20,$N$5:$P$11,3,FALSE()) -> 2723.75 | L20: =G20-H20 -> 131.25 | M20: =ABS((G20-H20)/G20) -> 0.045971979
A21: ='Raw Data'!A17 -> 44484 | B21: ='Raw Data'!B17 -> 6 | C21: ='Raw Data'!C17 -> Saturday | D21: ='Raw Data'!D17 -> 0 | E21: ='Raw Data'!E17 -> 0 | F21: ='Raw Data'!F17 -> 0 | G21: ='Raw Data'!G17 -> 2777 | H21: =VLOOKUP(B21,$N$5:$P$11,3,FALSE()) -> 2428.2222 | L21: =G21-H21 -> 348.77778 | M21: =ABS((G21-H21)/G21) -> 0.12559517
A22: ='Raw Data'!A18 -> 44485 | B22: ='Raw Data'!B18 -> 7 | C22: ='Raw Data'!C18 -> Sunday | D22: ='Raw Data'!D18 -> 0 | E22: ='Raw Data'!E18 -> 1 | F22: ='Raw Data'!F18 -> 0 | G22: ='Raw Data'!G18 -> 3605 | H22: =VLOOKUP(B22,$N$5:$P$11,3,FALSE()) -> 3670 | L22: =G22-H22 -> -65 | M22: =ABS((G22-H22)/G22) -> 0.018030513
A23: ='Raw Data'!A19 -> 44486 | B23: ='Raw Data'!B19 -> 1 | C23: ='Raw Data'!C19 -> Monday | D23: ='Raw Data'!D19 -> 0 | E23: ='Raw Data'!E19 -> 1 | F23: ='Raw Data'!F19 -> 0 | G23: ='Raw Data'!G19 -> 2351 | H23: =VLOOKUP(B23,$N$5:$P$11,3,FALSE()) -> 3684.1111 | L23: =G23-H23 -> -1333.1111 | M23: =ABS((G23-H23)/G23) -> 0.56704003
... A39: ='Raw Data'!A35 -> 44502 | B39: ='Raw Data'!B35 -> 3 | C39: ='Raw Data'!C35 -> Wednesday | D39: ='Raw Data'!D35 -> 1 | E39: ='Raw Data'!E35 -> 0 | F39: ='Raw Data'!F35 -> 0 | G39: ='Raw Data'!G35 -> 1748 | H39: =VLOOKUP(B39,$N$5:$P$11,3,FALSE()) -> 2795.5 | L39: =G39-H39 -> -1047.5 | M39: =ABS((G39-H39)/G39) -> 0.59925629
A40: ='Raw Data'!A36 -> 44503 | B40: ='Raw Data'!B36 -> 4 | C40: ='Raw Data'!C36 -> Thursday | D40: ='Raw Data'!D36 -> 1 | E40: ='Raw Data'!E36 -> 0 | F40: ='Raw Data'!F36 -> 0 | G40: ='Raw Data'!G36 -> 2186 | H40: =VLOOKUP(B40,$N$5:$P$11,3,FALSE()) -> 2911.375 | L40: =G30-H40 -> 2576.625 | M40: =ABS((G30-H40)/G30) -> 0.46950164
A41: ='Raw Data'!A37 -> 44504 | B41: ='Raw Data'!B37 -> 5 | C41: ='Raw Data'!C37 -> Friday | D41: ='Raw Data'!D37 -> 1 | E41: ='Raw Data'!E37 -> 0 | F41: ='Raw Data'!F37 -> 0 | G41: ='Raw Data'!G37 -> 1983 | H41: =VLOOKUP(B41,$N$5:$P$11,3,FALSE()) -> 2723.75 | L41: =G31-H41 -> -532.75 | M41: =ABS((G31-H41)/G31) -> 0.24315381
A42: ='Raw Data'!A38 -> 44505 | B42: ='Raw Data'!B38 -> 6 | C42: ='Raw Data'!C38 -> Saturday | D42: ='Raw Data'!D38 -> 1 | E42: ='Raw Data'!E38 -> 0 | F42: ='Raw Data'!F38 -> 0 | G42: ='Raw Data'!G38 -> 2214 | H42: =VLOOKUP(B42,$N$5:$P$11,3,FALSE()) -> 2428.2222 | L42: =G32-H42 -> -484.22222 | M42: =ABS((G32-H42)/G32) -> 0.24908551
A43: ='Raw Data'!A39 -> 44506 | B43: ='Raw Data'!B39 -> 7 | C43: ='Raw Data'!C39 -> Sunday | D43: ='Raw Data'!D39 -> 1 | E43: ='Raw Data'!E39 -> 1 | F43: ='Raw Data'!F39 -> 0 | G43: ='Raw Data'!G39 -> 4930 | H43: =VLOOKUP(B43,$N$5:$P$11,3,FALSE()) -> 3670 | L43: =G33-H43 -> -715 | M43: =ABS((G33-H43)/G33) -> 0.24196277
A44: ='Raw Data'!A40 -> 44507 | B44: ='Raw Data'!B40 -> 1 | C44: ='Raw Data'!C40 -> Monday | D44: ='Raw Data'!D40 -> 1 | E44: ='Raw Data'!E40 -> 1 | F44: ='Raw Data'!F40 -> 0 | G44: ='Raw Data'!G30 -> 4089 | H44: =VLOOKUP(B44,$N$5:$P$11,3,FALSE()) -> 3684.1111 | L44: =G34-H44 -> 404.88889 | M44: =ABS((G34-H44)/G34) -> 0.099019048
A45: ='Raw Data'!A41 -> 44508 | B45: ='Raw Data'!B41 -> 2 | C45: ='Raw Data'!C41 -> Tuesday | D45: ='Raw Data'!D41 -> 0 | E45: ='Raw Data'!E41 -> 0 | F45: ='Raw Data'!F41 -> 0 | G45: ='Raw Data'!G31 -> 2104 | H45: =VLOOKUP(B45,$N$5:$P$11,3,FALSE()) -> 2327.75 | L45: =G35-H45 -> -223.75 | M45: =ABS((G35-H45)/G35) -> 0.10634506
A46: ='Raw Data'!A42 -> 44509 | B46: ='Raw Data'!B42 -> 3 | C46: ='Raw Data'!C42 -> Wednesday | D46: ='Raw Data'!D42 -> 0 | E46: ='Raw Data'!E42 -> 0 | F46: ='Raw Data'!F42 -> 1 | G46: ='Raw Data'!G32 -> 4240 | H46: =VLOOKUP(B46,$N$5:$P$11,3,FALSE()) -> 2795.5 | L46: =G36-H46 -> 1444.5 | M46: =ABS((G36-H46)/G36) -> 0.34068396
A47: ='Raw Data'!A43 -> 44510 | B47: ='Raw Data'!B43 -> 4 | C47: ='Raw Data'!C43 -> Thursday | D47: ='Raw Data'!D43 -> 0 | E47: ='Raw Data'!E43 -> 0 | F47: ='Raw Data'!F43 -> 0 | G47: ='Raw Data'!G33 -> 2190 | H47: =VLOOKUP(B47,$N$5:$P$11,3,FALSE()) -> 2911.375 | L47: =G37-H47 -> -721.375 | M47: =ABS((G37-H47)/G37) -> 0.32939498
A48: ='Raw Data'!A44 -> 44511 | B48: ='Raw Data'!B44 -> 5 | C48: ='Raw Data'!C44 -> Friday | D48: ='Raw Data'!D44 -> 0 | E48: ='Raw Data'!E44 -> 0 | F48: ='Raw Data'!F44 -> 0 | G48: ='Raw Data'!G34 -> 1950 | H48: =VLOOKUP(B48,$N$5:$P$11,3,FALSE()) -> 2723.75 | L48: =G38-H48 -> -773.75 | M48: =ABS((G38-H48)/G38) -> 0.39679487
A49: ='Raw Data'!A45 -> 44512 | B49: ='Raw Data'!B45 -> 6 | C49: ='Raw Data'!C45 -> Saturday | D49: ='Raw Data'!D45 -> 0 | E49: ='Raw Data'!E45 -> 0 | F49: ='Raw Data'!F45 -> 0 | G49: ='Raw Data'!G35 -> 1748 | H49: =VLOOKUP(B49,$N$5:$P$11,3,FALSE()) -> 2428.2222 | L49: =G39-H49 -> -680.22222 | M49: =ABS((G39-H49)/G39) -> 0.38914315
A50: ='Raw Data'!A46 -> 44513 | B50: ='Raw Data'!B46 -> 7 | C50: ='Raw Data'!C46 -> Sunday | D50: ='Raw Data'!D46 -> 0 | E50: ='Raw Data'!E46 -> 1 | F50: ='Raw Data'!F46 -> 0 | G50: ='Raw Data'!G36 -> 2186 | H50: =VLOOKUP(B50,$N$5:$P$11,3,FALSE()) -> 3670 | L50: =G50-H50 -> -1484 | M50: =ABS((G50-H50)/G50) -> 0.67886551
A51: ='Raw Data'!A47 -> 44514 | B51: ='Raw Data'!B47 -> 1 | C51: ='Raw Data'!C47 -> Monday | D51: ='Raw Data'!D47 -> 0 | E51: ='Raw Data'!E47 -> 1 | F51: ='Raw Data'!F47 -> 0 | G51: ='Raw Data'!G37 -> 1983 | H51: =VLOOKUP(B51,$N$5:$P$11,3,FALSE()) -> 3684.1111 | L51: =G51-H51 -> -1701.1111 | M51: =ABS((G51-H51)/G51) -> 0.85784726
A52: ='Raw Data'!A48 -> 44515 | B52: ='Raw Data'!B48 -> 2 | C52: ='Raw Data'!C48 -> Tuesday | D52: ='Raw Data'!D48 -> 0 | E52: ='Raw Data'!E48 -> 0 | F52: ='Raw Data'!F48 -> 0 | G52: ='Raw Data'!G38 -> 2214 | H52: =VLOOKUP(B52,$N$5:$P$11,3,FALSE()) -> 2327.75 | L52: =G52-H52 -> -113.75 | M52: =ABS((G52-H52)/G52) -> 0.051377597
A53: ='Raw Data'!A49 -> 44516 | B53: ='Raw Data'!B49 -> 3 | C53: ='Raw Data'!C49 -> Wednesday | D53: ='Raw Data'!D49 -> 0 | E53: ='Raw Data'!E49 -> 0 | F53: ='Raw Data'!F49 -> 0 | G53: ='Raw Data'!G39 -> 4930 | H53: =VLOOKUP(B53,$N$5:$P$11,3,FALSE()) -> 2795.5 | L53: =G53-H53 -> 2134.5 | M53: =ABS((G53-H53)/G53) -> 0.43296146
A54: ='Raw Data'!A50 -> 44517 | B54: ='Raw Data'!B50 -> 4 | C54: ='Raw Data'!C50 -> Thursday | D54: ='Raw Data'!D50 -> 0 | E54: ='Raw Data'!E50 -> 0 | F54: ='Raw Data'!F50 -> 0 | G54: ='Raw Data'!G50 -> 2159 | H54: =VLOOKUP(B54,$N$5:$P$11,3,FALSE()) -> 2911.375 | L54: =G54-H54 -> -752.375 | M54: =ABS((G54-H54)/G54) -> 0.34848309
A55: ='Raw Data'!A51 -> 44518 | B55: ='Raw Data'!B51 -> 5 | C55: ='Raw Data'!C51 -> Friday | D55: ='Raw Data'!D51 -> 0 | E55: ='Raw Data'!E51 -> 0 | F55: ='Raw Data'!F51 -> 0 | G55: ='Raw Data'!G51 -> 2747 | H55: =VLOOKUP(B55,$N$5:$P$11,3,FALSE()) -> 2723.75 | L55: =G55-H55 -> 23.25 | M55: =ABS((G55-H55)/G55) -> 0.0084637787
...

Sheet Model 3 - Linear Regression
A1: MODEL 3 — Multiple Linear Regression (3 Indicators: Holiday, Weekend, Newsletter)
A2: Method: Sales = β₀ + β₁×Holiday + β₂×Weekend + β₃×Newsletter. Coefficients estimated with Excel LINEST function. This model accounts for all three business drivers simultaneously.
A3: Regression equation: Sales = β₀ + β₁ × Holiday + β₂ × Weekend + β₃ × Newsletter [all coefficients from LINEST below]
A4: Coefficient | B4: Symbol | C4: Value (from LINEST) | D4: Interpretation | E4: Business meaning
A5: Intercept | B5: β₀ | C5: =INDEX(LINEST('Raw Data'!G3:G61,'Raw Data'!D3:F61,TRUE(),FALSE()),1,4) -> 2503.8509 | D5: Base daily sales (Holiday=0, Weekend=0, Newsletter=0) | E5: Typical quiet weekday sales
A6: Holiday effect | B6: β₁ | C6: =INDEX(LINEST('Raw Data'!G3:G61,'Raw Data'!D3:F61,TRUE(),FALSE()),1,3) -> -413.70365 | D6: Change in sales when Holiday=1 | E6: Expected: negative — fewer customers on holidays
A7: Weekend effect | B7: β₂ | C7: =INDEX(LINEST('Raw Data'!G3:G61,'Raw Data'!D3:F61,TRUE(),FALSE()),1,2) -> 1265.1388 | D7: Change in sales when Weekend=1 | E7: Expected: positive — weekend browsing/shopping
A8: Newsletter effect | B8: β₃ | C8: =INDEX(LINEST('Raw Data'!G3:G61,'Raw Data'!D3:F61,TRUE(),FALSE()),1,1) -> 3133.3837 | D8: Change in sales when Newsletter=1 | E8: Expected: strongly positive — email drives purchases
A9: Date | B9: Day# | C9: Day Name | D9: Holiday? | E9: Weekend? | F9: Newsletter? | G9: Real Sales | H9: Regression Forecast | I9: Difference | J9: Abs Error Rate | K9: Segment | L9: Formula reference
A10: LEARNING DATA (59 obs) Oct 1 – Nov 28, 2021
A11: ='Raw Data'!A4 -> 44471 | B11: ='Raw Data'!B4 -> 7 | C11: ='Raw Data'!C4 -> Sunday | D11: ='Raw Data'!D4 -> 0 | E11: ='Raw Data'!E4 -> 1 | F11: ='Raw Data'!F4 -> 0 | G11: ='Raw Data'!G3 -> 2042 | H11: =$C$5+$C$6*D11+$C$7*E11+$C$8*F11 -> 3768.9897 | I11: =G11-H11 -> -1726.9897 | J11: =ABS((G11-H11)/G11) -> 0.84573443 | K11: Learning
A12: ='Raw Data'!A5 -> 44472 | B12: ='Raw Data'!B5 -> 1 | C12: ='Raw Data'!C5 -> Monday | D12: ='Raw Data'!D5 -> 0 | E12: ='Raw Data'!E5 -> 1 | F12: ='Raw Data'!F5 -> 0 | G12: ='Raw Data'!G5 -> 4289 | H12: =$C$5+$C$6*D12+$C$7*E12+$C$8*F12 -> 3768.9897 | I12: =G12-H12 -> 520.0103 | J12: =ABS((G12-H12)/G12) -> 0.12124278 | K12: Learning
A13: ='Raw Data'!A6 -> 44473 | B13: ='Raw Data'!B6 -> 2 | C13: ='Raw Data'!C6 -> Tuesday | D13: ='Raw Data'!D6 -> 0 | E13: ='Raw Data'!E6 -> 0 | F13: ='Raw Data'!F6 -> 0 | G13: ='Raw Data'!G6 -> 2454 | H13: =$C$5+$C$6*D13+$C$7*E13+$C$8*F13 -> 2503.8509 | I13: =G13-H13 -> -49.850865 | J13: =ABS((G13-H13)/G13) -> 0.020314126 | K13: Learning
A14: ='Raw Data'!A7 -> 44474 | B14: ='Raw Data'!B7 -> 3 | C14: ='Raw Data'!C7 -> Wednesday | D14: ='Raw Data'!D7 -> 0 | E14: ='Raw Data'!E7 -> 0 | F14: ='Raw Data'!F7 -> 0 | G14: ='Raw Data'!G7 -> 2544 | H14: =$C$5+$C$6*D14+$C$7*E14+$C$8*F14 -> 2503.8509 | I14: =G14-H14 -> 40.149135 | J14: =ABS((G14-H14)/G14) -> 0.015781893 | K14: Learning
A15: ='Raw Data'!A8 -> 44475 | B15: ='Raw Data'!B8 -> 4 | C15: ='Raw Data'!C8 -> Thursday | D15: ='Raw Data'!D8 -> 0 | E15: ='Raw Data'!E8 -> 0 | F15: ='Raw Data'!F8 -> 0 | G15: ='Raw Data'!G8 -> 2686 | H15: =$C$5+$C$6*D15+$C$7*E15+$C$8*F15 -> 2503.8509 | I15: =G15-H15 -> 182.14913 | J15: =ABS((G15-H15)/G15) -> 0.067814272 | K15: Learning
A16: ='Raw Data'!A9 -> 44476 | B16: ='Raw Data'!B9 -> 5 | C16: ='Raw Data'!C9 -> Friday | D16: ='Raw Data'!D9 -> 0 | E16: ='Raw Data'!E9 -> 0 | F16: ='Raw Data'!F9 -> 0 | G16: ='Raw Data'!G9 -> 2792 | H16: =$C$5+$C$6*D16+$C$7*E16+$C$8*F16 -> 2503.8509 | I16: =G16-H16 -> 288.14913 | J16: =ABS((G16-H16)/G16) -> 0.10320528 | K16: Learning
A17: ='Raw Data'!A10 -> 44477 | B17: ='Raw Data'!B10 -> 6 | C17: ='Raw Data'!C10 -> Saturday | D17: ='Raw Data'!D10 -> 0 | E17: ='Raw Data'!E10 -> 0 | F17: ='Raw Data'!F10 -> 0 | G17: ='Raw Data'!G10 -> 2246 | H17: =$C$5+$C$6*D17+$C$7*E17+$C$8*F17 -> 2503.8509 | I17: =G17-H17 -> -257.85087 | J17: =ABS((G17-H17)/G17) -> 0.11480448 | K17: Learning
A18: ='Raw Data'!A11 -> 44478 | B18: ='Raw Data'!B11 -> 7 | C18: ='Raw Data'!C11 -> Sunday | D18: ='Raw Data'!D11 -> 0 | E18: ='Raw Data'!E11 -> 1 | F18: ='Raw Data'!F11 -> 0 | G18: ='Raw Data'!G11 -> 4078 | H18: =$C$5+$C$6*D18+$C$7*E18+$C$8*F18 -> 3768.9897 | I18: =G18-H18 -> 309.0103 | J18: =ABS((G18-H18)/G18) -> 0.075774963 | K18: Learning
A19: ='Raw Data'!A12 -> 44479 | B19: ='Raw Data'!B12 -> 1 | C19: ='Raw Data'!C12 -> Monday | D19: ='Raw Data'!D12 -> 0 | E19: ='Raw Data'!E12 -> 1 | F19: ='Raw Data'!F12 -> 0 | G19: ='Raw Data'!G12 -> 3949 | H19: =$C$5+$C$6*D19+$C$7*E19+$C$8*F19 -> 3768.9897 | I19: =G19-H19 -> 180.0103 | J19: =ABS((G19-H19)/G19) -> 0.045583768 | K19: Learning
A20: ='Raw Data'!A13 -> 44480 | B20: ='Raw Data'!B13 -> 2 | C20: ='Raw Data'!C13 -> Tuesday | D20: ='Raw Data'!D13 -> 0 | E20: ='Raw Data'!E13 -> 0 | F20: ='Raw Data'!F13 -> 0 | G20: ='Raw Data'!G13 -> 2687 | H20: =$C$5+$C$6*D20+$C$7*E20+$C$8*F20 -> 2503.8509 | I20: =G20-H20 -> 183.14913 | J20: =ABS((G20-H20)/G20) -> 0.068161196 | K20: Learning
A21: ='Raw Data'!A14 -> 44481 | B21: ='Raw Data'!B14 -> 3 | C21: ='Raw Data'!C14 -> Wednesday | D21: ='Raw Data'!D14 -> 0 | E21: ='Raw Data'!E14 -> 0 | F21: ='Raw Data'!F14 -> 0 | G21: ='Raw Data'!G14 -> 2737 | H21: =$C$5+$C$6*D21+$C$7*E21+$C$8*F21 -> 2503.8509 | I21: =G21-H21 -> 233.14913 | J21: =ABS((G21-H21)/G21) -> 0.085184192 | K21: Learning
A22: ='Raw Data'!A15 -> 44482 | B22: ='Raw Data'!B15 -> 4 | C22: ='Raw Data'!C15 -> Thursday | D22: ='Raw Data'!D15 -> 0 | E22: ='Raw Data'!E15 -> 0 | F22: ='Raw Data'!F15 -> 1 | G22: ='Raw Data'!G15 -> 5817 | H22: =$C$5+$C$6*D22+$C$7*E22+$C$8*F22 -> 5637.2346 | I22: =G22-H22 -> 179.76545 | J22: =ABS((G22-H22)/G22) -> 0.030903464 | K22: Learning
A23: ='Raw Data'!A16 -> 44483 | B23: ='Raw Data'!B16 -> 5 | C23: ='Raw Data'!C16 -> Friday | D23: ='Raw Data'!D16 -> 0 | E23: ='Raw Data'!E16 -> 0 | F23: ='Raw Data'!F16 -> 0 | G23: ='Raw Data'!G16 -> 2855 | H23: =$C$5+$C$6*D23+$C$7*E23+$C$8*F23 -> 2503.8509 | I23: =G23-H23 -> 351.14913 | J23: =ABS((G23-H23)/G23) -> 0.12299444 | K23: Learning
... A39: ='Raw Data'!A32 -> 44499 | B39: ='Raw Data'!B32 -> 7 | C39: ='Raw Data'!C32 -> Sunday | D39: ='Raw Data'!D32 -> 1 | E39: ='Raw Data'!E32 -> 1 | F39: ='Raw Data'!F32 -> 0 | G39: ='Raw Data'!G32 -> 4240 | H39: =$C$5+$C$6*D39+$C$7*E39+$C$8*F39 -> 3355.286 | I39: =G39-H39 -> 884.71395 | J39: =ABS((G39-H39)/G39) -> 0.20865895 | K39: Learning
A40: ='Raw Data'!A33 -> 44500 | B40: ='Raw Data'!B33 -> 1 | C40: ='Raw Data'!C33 -> Monday | D40: ='Raw Data'!D33 -> 1 | E40: ='Raw Data'!E33 -> 1 | F40: ='Raw Data'!F33 -> 0 | G40: ='Raw Data'!G33 -> 2190 | H40: =$C$5+$C$6*D40+$C$7*E40+$C$8*F40 -> 3355.286 | I40: =G30-H40 -> -836.28605 | J40: =ABS((G30-H40)/G30) -> 0.33199129 | K40: Learning
A41: ='Raw Data'!A34 -> 44501 | B41: ='Raw Data'!B34 -> 2 | C41: ='Raw Data'!C34 -> Tuesday | D41: ='Raw Data'!D34 -> 1 | E41: ='Raw Data'!E34 -> 0 | F41: ='Raw Data'!F34 -> 0 | G41: ='Raw Data'!G34 -> 1950 | H41: =$C$5+$C$6*D41+$C$7*E41+$C$8*F41 -> 2090.1472 | I41: =G31-H41 -> 624.85279 | J41: =ABS((G31-H41)/G31) -> 0.23014836 | K41: Learning
A42: ='Raw Data'!A35 -> 44502 | B42: ='Raw Data'!B35 -> 3 | C42: ='Raw Data'!C35 -> Wednesday | D42: ='Raw Data'!D35 -> 1 | E42: ='Raw Data'!E35 -> 0 | F42: ='Raw Data'!F35 -> 0 | G42: ='Raw Data'!G35 -> 1748 | H42: =$C$5+$C$6*D42+$C$7*E42+$C$8*F42 -> 2090.1472 | I42: =G32-H42 -> 372.85279 | J42: =ABS((G32-H42)/G32) -> 0.15138156 | K42: Learning
A43: ='Raw Data'!A36 -> 44503 | B43: ='Raw Data'!B36 -> 4 | C43: ='Raw Data'!C36 -> Thursday | D43: ='Raw Data'!D36 -> 1 | E43: ='Raw Data'!E36 -> 0 | F43: ='Raw Data'!F36 -> 0 | G43: ='Raw Data'!G36 -> 2186 | H43: =$C$5+$C$6*D43+$C$7*E43+$C$8*F43 -> 2090.1472 | I43: =G33-H43 -> 3397.8528 | J43: =ABS((G33-H43)/G33) -> 0.61914227 | K43: Learning
A44: ='Raw Data'!A37 -> 44504 | B44: ='Raw Data'!B37 -> 5 | C44: ='Raw Data'!C37 -> Friday | D44: ='Raw Data'!D37 -> 1 | E44: ='Raw Data'!E37 -> 0 | F44: ='Raw Data'!F37 -> 0 | G44: ='Raw Data'!G37 -> 1983 | H44: =$C$5+$C$6*D44+$C$7*E44+$C$8*F44 -> 2090.1472 | I44: =G34-H44 -> 100.85279 | J44: =ABS((G34-H44)/G34) -> 0.046030483 | K44: Learning
A45: ='Raw Data'!A38 -> 44505 | B45: ='Raw Data'!B38 -> 6 | C45: ='Raw Data'!C38 -> Saturday | D45: ='Raw Data'!D38 -> 1 | E45: ='Raw Data'!E38 -> 0 | F45: ='Raw Data'!F38 -> 0 | G45: ='Raw Data'!G38 -> 2214 | H45: =$C$5+$C$6*D45+$C$7*E45+$C$8*F45 -> 2090.1472 | I45: =G35-H45 -> -146.14721 | J45: =ABS((G35-H45)/G35) -> 0.075178607 | K45: Learning
A46: ='Raw Data'!A39 -> 44506 | B46: ='Raw Data'!B39 -> 7 | C46: ='Raw Data'!C39 -> Sunday | D46: ='Raw Data'!D39 -> 1 | E46: ='Raw Data'!E39 -> 1 | F46: ='Raw Data'!F39 -> 0 | G46: ='Raw Data'!G39 -> 4930 | H46: =$C$5+$C$6*D46+$C$7*E46+$C$8*F46 -> 3355.286 | I46: =G36-H46 -> -400.28605 | J46: =ABS((G36-H46)/G36) -> 0.13546059 | K46: Learning
A47: ='Raw Data'!A40 -> 44507 | B47: ='Raw Data'!B40 -> 1 | C47: ='Raw Data'!C40 -> Monday | D47: ='Raw Data'!D40 -> 1 | E47: ='Raw Data'!E40 -> 1 | F47: ='Raw Data'!F40 -> 0 | G47: ='Raw Data'!G30 -> 4089 | H47: =$C$5+$C$6*D47+$C$7*E47+$C$8*F47 -> 3355.286 | I47: =G37-H47 -> 733.71395 | J47: =ABS((G37-H47)/G37) -> 0.17943604 | K47: Learning
A48: ='Raw Data'!A41 -> 44508 | B48: ='Raw Data'!B41 -> 2 | C48: ='Raw Data'!C41 -> Tuesday | D48: ='Raw Data'!D41 -> 0 | E48: ='Raw Data'!E41 -> 0 | F48: ='Raw Data'!F41 -> 0 | G48: ='Raw Data'!G31 -> 2104 | H48: =$C$5+$C$6*D48+$C$7*E48+$C$8*F48 -> 2503.8509 | I48: =G38-H48 -> -399.85087 | J48: =ABS((G38-H48)/G38) -> 0.19004319 | K48: Learning
A49: ='Raw Data'!A42 -> 44509 | B49: ='Raw Data'!B42 -> 3 | C49: ='Raw Data'!C42 -> Wednesday | D49: ='Raw Data'!D42 -> 0 | E49: ='Raw Data'!E42 -> 0 | F49: ='Raw Data'!F42 -> 1 | G49: ='Raw Data'!G32 -> 4240 | H49: =$C$5+$C$6*D49+$C$7*E49+$C$8*F49 -> 5637.2346 | I49: =G39-H49 -> -1397.2346 | J49: =ABS((G39-H49)/G39) -> 0.32953645 | K49: Learning
A50: ='Raw Data'!A43 -> 44510 | B50: ='Raw Data'!B43 -> 4 | C50: ='Raw Data'!C43 -> Thursday | D50: ='Raw Data'!D43 -> 0 | E50: ='Raw Data'!E43 -> 0 | F50: ='Raw Data'!F43 -> 0 | G50: ='Raw Data'!G33 -> 2190 | H50: =$C$5+$C$6*D50+$C$7*E50+$C$8*F50 -> 2503.8509 | I50: =G50-H50 -> -313.85087 | J50: =ABS((G50-H50)/G50) -> 0.1433109 | K50: Learning
A51: ='Raw Data'!A44 -> 44511 | B51: ='Raw Data'!B44 -> 5 | C51: ='Raw Data'!C44 -> Friday | D51: ='Raw Data'!D44 -> 0 | E51: ='Raw Data'!E44 -> 0 | F51: ='Raw Data'!F44 -> 0 | G51: ='Raw Data'!G34 -> 1950 | H51: =$C$5+$C$6*D51+$C$7*E51+$C$8*F51 -> 2503.8509 | I51: =G51-H51 -> -553.85087 | J51: =ABS((G51-H51)/G51) -> 0.28402608 | K51: Learning
A52: ='Raw Data'!A45 -> 44512 | B52: ='Raw Data'!B45 -> 6 | C52: ='Raw Data'!C45 -> Saturday | D52: ='Raw Data'!D45 -> 0 | E52: ='Raw Data'!E45 -> 0 | F52: ='Raw Data'!F45 -> 0 | G52: ='Raw Data'!G35 -> 1748 | H52: =$C$5+$C$6*D52+$C$7*E52+$C$8*F52 -> 2503.8509 | I52: =G52-H52 -> -755.85087 | J52: =ABS((G52-H52)/G52) -> 0.43240896 | K52: Learning
A53: ='Raw Data'!A46 -> 44513 | B53: ='Raw Data'!B46 -> 7 | C53: ='Raw Data'!C46 -> Sunday | D53: ='Raw Data'!D46 -> 0 | E53: ='Raw Data'!E46 -> 1 | F53: ='Raw Data'!F46 -> 0 | G53: ='Raw Data'!G36 -> 2186 | H53: =$C$5+$C$6*D53+$C$7*E53+$C$8*F53 -> 3768.9897 | I53: =G53-H53 -> -1582.9897 | J53: =ABS((G53-H53)/G53) -> 0.72414899 | K53: Learning
A54: ='Raw Data'!A47 -> 44514 | B54: ='Raw Data'!B47 -> 1 | C54: ='Raw Data'!C47 -> Monday | D54: ='Raw Data'!D47 -> 0 | E54: ='Raw Data'!E47 -> 1 | F54: ='Raw Data'!F47 -> 0 | G54: ='Raw Data'!G37 -> 1983 | H54: =$C$5+$C$6*D54+$C$7*E54+$C$8*F54 -> 3768.9897 | I54: =G54-H54 -> -1785.9897 | J54: =ABS((G54-H54)/G54) -> 0.90065038 | K54: Learning
A55: ='Raw Data'!A48 -> 44515 | B55: ='Raw Data'!B48 -> 2 | C55: ='Raw Data'!C48 -> Tuesday | D55: ='Raw Data'!D48 -> 0 | E55: ='Raw Data'!E48 -> 0 | F55: ='Raw Data'!F48 -> 0 | G55: ='Raw Data'!G38 -> 2214 | H55: =$C$5+$C$6*D55+$C$7*E55+$C$8*F55 -> 2503.8509 | I55: =G55-H55 -> -289.85087 | J55: =ABS((G55-H55)/G55) -> 0.13091728 | K55: Learning
...

Sheet Analysis & Summary
A1: LA ROCHE-POSAY — Sales Forecasting: Model Comparison & Full Analysis
A4: SECTION 1 — Descriptive Statistics on Learning Data
A5: Statistic | B5: Formula Used | C5: All Learning Data | D5: Weekdays (Wknd=0) | E5: Weekends (Wknd=1) | F5: Holiday Days | G5: Newsletter Days | H5: Non-Newsletter Days
A6: Count (n) | B6: COUNT / COUNTIF | C6: =COUNT('Raw Data'!G3:G61) -> 59 | D6: =COUNTIF('Raw Data'!E4:E62,0) -> 41 | E6: =COUNTIF('Raw Data'!E4:E62,1) -> 18 | F6: =COUNTIF('Raw Data'!D3:D61,1) -> 14 | G6: =COUNTIF('Raw Data'!F4:F61,1) -> 3 | H6: =COUNTIF('Raw Data'!F4:F61,0) -> 55
A7: Mean (Average) | B7: AVERAGE / AVERAGEIF | C7: =AVERAGE('Raw Data'!G3:G61) -> 2950.9831 | D7: =AVERAGEIF('Raw Data'!E4:E62,0,'Raw Data'!G3:G61) -> 2907.9024 | E7: =AVERAGEIF('Raw Data'!E4:E62,1,'Raw Data'!G3:G61) -> 3049.1111 | F7: =AVERAGEIF('Raw Data'!D3:D61,1,'Raw Data'!G3:G61) -> 2675.4286 | G7: =AVERAGEIF('Raw Data'!F4:F61,1,'Raw Data'!G3:G61) -> 2600.3333 | H7: =AVERAGEIF('Raw Data'!F4:F61,0,'Raw Data'!G3:G61) -> 2970.4364
A8: Minimum | B8: MIN | C8: =MIN('Raw Data'!G3:G61) -> 1748 | D8: — | E8: — | F8: — | G8: — | H8: —
A9: Maximum | B9: MAX | C9: =MAX('Raw Data'!G3:G61) -> 6592 | D9: — | E9: — | F9: — | G9: — | H9: —
A10: Range (Max-Min) | B10: MAX-MIN | C10: =MAX('Raw Data'!G3:G61)-MIN('Raw Data'!G3:G61) -> 4844 | D10: — | E10: — | F10: — | G10: — | H10: —
A11: Median (Q2) | B11: MEDIAN | C11: =MEDIAN('Raw Data'!G3:G61) -> 2656 | D11: — | E11: — | F11: — | G11: — | H11: —
A12: Q1 (25th pctile) | B12: QUARTILE | C12: =QUARTILE('Raw Data'!G3:G61,1) -> 2190.5 | D12: — | E12: — | F12: — | G12: — | H12: —
A13: Q3 (75th pctile) | B13: QUARTILE | C13: =QUARTILE('Raw Data'!G3:G61,3) -> 3093.5 | D13: — | E13: — | F13: — | G13: — | H13: —
A14: IQR (Q3-Q1) | B14: Q3-Q1 | C14: =QUARTILE('Raw Data'!G3:G61,3)-QUARTILE('Raw Data'!G3:G61,1) -> 903 | D14: — | E14: — | F14: — | G14: — | H14: —
A15: Std Deviation | B15: STDEV | C15: =STDEV('Raw Data'!G3:G61) -> 1060.8787 | D15: — | E15: — | F15: — | G15: — | H15: —
A16: Variance | B16: VAR | C16: =VAR('Raw Data'!G3:G61) -> 1125463.6 | D16: — | E16: — | F16: — | G16: — | H16: —
A17: Coeff of Variation | B17: StdDev/Mean | C17: =STDEV('Raw Data'!G3:G61)/AVERAGE('Raw Data'!G3:G61) -> 0.3595001 | D17: — | E17: — | F17: — | G17: — | H17: —
A19: SECTION 2 — Model Performance Comparison (MAPE on Testing Data, Nov 29 – Dec 13)
A20: Model | B20: Method Description | C20: No. of Parameters | D20: MAPE | E20: Rank (1=best) | F20: vs. Model 1 | G20: Improvement | H20: Assessment
A21: Model 1 | B21: Global Average — one number for all days | C21: 1 (global mean) | D21: =AVERAGE('Model 1 - Global Average'!J66:J79) -> 0.17945199 | E21: =IF(ISNUMBER(D21),RANK(D21,D21:D23,1),"—") -> 3 | F21: Baseline | G21: — | H21: =IF(ISNUMBER(D21),IF(D21<0.2,"Acceptable baseline","Poor"),"Pending") -> Acceptable baseline
A22: Model 2 | B22: Day-of-Week Avg — 7 day-specific averages | C22: 7 (one per weekday) | D22: =AVERAGE('Model 2 - Day of Week Avg'!M68:M81) -> 0.12425566 | E22: =IF(ISNUMBER(D22),RANK(D22,D21:D23,1),"—") -> 2 | F22: =IF(ISNUMBER(D21)*ISNUMBER(D22),IF(D22<D21,"✓ Better","✗ Worse"),"—") -> ✓ Better | G22: =IF(ISNUMBER(D21)*ISNUMBER(D22),TEXT(ABS(D21-D22),"0.00%")&" reduction","—") -> 5.52% reduction | H22: =IF(ISNUMBER(D22),IF(D22<0.15,"Good","Review"),"Pending") -> Good
A23: Model 3 | B23: Linear Regression — 3 business indicators | C23: 4 (β₀,β₁,β₂,β₃) | D23: =AVERAGE('Model 3 - Linear Regression'!J71:J84) -> 0.091212552 | E23: =IF(ISNUMBER(D23),RANK(D23,D21:D23,1),"—") -> 1 | F23: =IF(ISNUMBER(D21)*ISNUMBER(D23),IF(D23<D21,"✓ Better","✗ Worse"),"—") -> ✓ Better | G23: =IF(ISNUMBER(D21)*ISNUMBER(D23),TEXT(ABS(D21-D23),"0.00%")&" reduction","—") -> 8.82% reduction | H23: =IF(ISNUMBER(D23),IF(D23<0.12,"✦ Best","Acceptable"),"Pending") -> ✦ Best
A25: =IF(ISNUMBER(D21)*ISNUMBER(D22)*ISNUMBER(D23),"✦ Best Model: "&IF(MIN(D21,D22,D23)=D21,"Model 1 (Global Avg) — MAPE="&TEXT(D21,"0.00%"),IF(MIN(D21,D22,D23)=D22,"Model 2 (Day-of-Week) — MAPE="&TEXT(D22,"0.00%"),"Model 3 (Linear Regression) — MAPE="&TEXT(D23,"0.00%"))),"Calculating...") -> ✦ Best Model: Model 3 (Linear Regression) — MAPE=9.12%
A27: SECTION 3 — Key Business Insights & Interpretation
A28: # | B28: Insight | C28: Detail
A29: 1 | B29: Newsletter is the strongest sales driver | C29: Newsletter days show dramatically higher sales vs. non-newsletter days. The β₃ coefficient from Linear Regression quantifies this exact uplift in units. This was also confirmed by the professor's module example (newsletters significantly increase sales). | G29: Schedule newsletters strategically; avoid holiday overlap. Combine with weekend for maximum uplift.
A30: 2 | B30: Weekends consistently outperform weekdays | C30: Weekend averages are significantly above weekday averages across the full learning period. The Day-of-Week model captures this pattern (Saturday/Sunday averages ~3,500–4,000 units vs ~2,500 weekday). The regression β₂ coefficient confirms direction and magnitude. | G30: Ensure stock and fulfilment capacity is ready by Friday. Do not reduce marketing on weekends.
A31: 3 | B31: Holidays suppress demand | C31: Holiday periods (school vacations, public holidays) show below-average sales. The β₁ coefficient is expected to be negative in the regression output. This aligns with reduced footfall in pharmacies and clinic closures. | G31: Reduce promotional investment on confirmed holiday periods. Reallocate budget to pre-holiday peaks.
A32: 4 | B32: Linear Regression is the best model | C32: Model 3 (Linear Regression) achieves the lowest MAPE because it simultaneously accounts for all three business drivers. Model 1 ignores all variation; Model 2 captures only day-of-week pattern but not newsletters or holidays. The multi-factorial approach is more robust. | G32: Use Model 3 as the production forecasting model. Retrain quarterly as new data accumulates.
A33: 5 | B33: MAPE interpretation & thresholds | C33: Industry benchmark: MAPE < 10% = Excellent, 10–20% = Good, 20–30% = Acceptable, >30% = Poor. Professor's reference MAPE for Linear Regression = 9.71% (module slides). High-sales outlier days (e.g. newsletter + weekend overlap) inflate MAPE — these are the hardest days to forecast. | G33: Consider segmenting error analysis by day type (normal vs. newsletter vs. holiday) for deeper insight.
A35: SECTION 4 — MAPE Formula
A36: Element | B36: Explanation / Formula
A37: Formula | B37: AVERAGE( ABS( (Forecasted Value - Real Value) / Real Value ) )
A38: In Excel (Model 1) | B38: Applied row-by-row to testing data in each model sheet (cols H vs G) | G38: Col H = Forecast, Col G = Real Sales
A39: Why AVERAGE? | B39: Takes mean error across all test observations — one summary metric | G39: Single number to compare models
A40: Why ABS? | B40: Without ABS, +/- errors cancel out, hiding real inaccuracy | G40: Prevents false sense of precision
A41: Why /Real? | B41: Normalises to %, comparable across different sales magnitudes | G41: Makes MAPE scale-independent
A42: Error threshold | B42: <10% Excellent | 10-20% Good | 20-30% Acceptable | >30% Poor | G42: Industry standard
